Workbook

Sheet Student_Data
A1: Student_ID | B1: Full_Name | C1: Gender | D1: Class | E1: Section | F1: City | G1: Maths | H1: Science | I1: English | J1: Hindi | K1: Social_Studies | L1: Total | M1: Percentage | N1: Attendance | O1: Status
A2: STD-1001 | B2: Priya Choudhary | C2: Female | D2: 10 | E2: A | F2: Chandigarh | G2: 45 | H2: 97 | I2: 58 | J2: 76 | K2: 71 | L2: 347 | M2: 39.4 | N2: 84 | O2: Pass
A3: STD-1002 | B3: Aarav Verma | C3: Male | D3: 7 | E3: C | F3: Kolkata | G3: 89 | H3: 83 | I3: 96 | J3: 54 | K3: 57 | L3: 379 | M3: 85.8 | N3: 89 | O3: Pass
A4: STD-1003 | B4: Sai Iyer | C4: Male | D4: 8 | E4: C | F4: Kolkata | G4: 48 | H4: 53 | I4: 61 | J4: 57 | K4: 81 | L4: 300 | M4: 20 | N4: 86 | O4: Pass
A5: STD-1004 | B5: Ananya Singh | C5: Female | D5: 8 | E5: C | F5: Kolkata | G5: 84 | H5: 56 | I5: 72 | J5: 92 | K5: 68 | L5: 372 | M5: 74.4 | N5: 84 | O5: Pass
A6: STD-1005 | B6: Shreya Kulkarni | C6: Male | D6: 8 | E6: C | F6: Chandigarh | G6: 71 | H6: 48 | I6: 54 | J6: 79 | K6: 92 | L6: 344 | M6: 68.8 | N6: 80 | O6: Pass
A7: STD-1006 | B7: Aarav Kulkarni | C7: Female | D7: 7 | E7: C | F7: Delhi | G7: 97 | H7: 44 | I7: 81 | J7: 69 | K7: 57 | L7: 348 | M7: 89.6 | N7: 66 | O7: Pass
A8: STD-1007 | B8: Meera Gupta | C8: Male | D8: 9 | E8: C | F8: Lucknow | G8: 93 | H8: 100 | I8: 58 | J8: 46 | K8: 67 | L8: 364 | M8: 82.8 | N8: 74 | O8: Pass
A9: STD-1008 | B9: Kavya Gupta | C9: Male | D9: 7 | E9: C | F9: Bhopal | G9: 63 | H9: 99 | I9: 44 | J9: 51 | K9: 59 | L9: 316 | M9: 63.2 | N9: 66 | O9: Pass
A10: STD-1009 | B10: Vivaan Verma | C10: Male | D10: 9 | E10: B | F10: Kolkata | G10: 81 | H10: 62 | I10: 65 | J10: 47 | K10: 57 | L10: 312 | M10: 92.4 | N10: 73 | O10: Pass
A11: STD-1010 | B11: Ananya Banerjee | C11: Female | D11: 10 | E11: A | F11: Kolkata | G11: 74 | H11: 63 | I11: 66 | J11: 60 | K11: 90 | L11: 353 | M11: 70.6 | N11: 88 | O11: Pass
A12: STD-1011 | B12: Aditya Choudhary | C12: Male | D12: 7 | E12: C | F12: Chandigarh | G12: 51 | H12: 40 | I12: 43 | J12: 99 | K12: 45 | L12: 278 | M12: 25.6 | N12: 98 | O12: Pass
A13: STD-1012 | B13: Priya Patel | C13: Female | D13: 6 | E13: A | F13: Jaipur | G13: 71 | H13: 43 | I13: 97 | J13: 41 | K13: 57 | L13: 309 | M13: 61.8 | N13: 75 | O13: Pass
... A501: STD-1500 | B501: Priya Choudhary | C501: Female | D501: 7 | E501: A | F501: Delhi | G501: 66 | H501: 54 | I501: 81 | J501: 44 | K501: 61 | L501: 306 | M501: 61.2 | N501: 71 | O501: Pass

Sheet Count
A1: 1. Total Number Of Student In Dataset : | B1: =COUNTA(Student_Data!A2:A501) -> 500
A3: 2.. Count how many students belong to each Class:
A12: 3. Identify how many students are from each City: | B12: City | C12: COUNTA of Student_ID
C13: 0
B14: Bhopal | C14: 64
B15: Chandigarh | C15: 69
B16: Delhi | C16: 55
B17: Jaipur | C17: 66
B18: Kolkata | C18: 64
B19: Lucknow | C19: 65
B20: Mumbai | C20: 64
B21: Patna | C21: 53
B22: Grand Total | C22: 500
A25: 4. Count students who scored more than 75 marks in Maths: | B25: =COUNTIF(Student_Data!G2:G501,">75") -> 207
A27: 5. Find how many students have Attendance greater than 90%: | B27: =COUNTIF(Student_Data!N2:N501,">90") -> 135

Sheet Countif
A1: 6. Count students who are Female and studying in Class 10: | B1: =COUNTIFS(Student_Data!C2:C501,"*Female*",Student_Data!D2:D501,"10") -> 60
A3: 7. Find the number of students who passed but have Attendance below 75%: | B3: =COUNTIFS(Student_Data!O2:O501,"Pass",Student_Data!N2:N501,"<75") -> 169
A5: 8. Count students who scored above 80 in both Maths and Science: | B5: =COUNTIFS(Student_Data!G2:G501,">80",Student_Data!H2:H501,">80") -> 51
A7: 9. Identify how many students belong to Section A in Class 9: | B7: =COUNTIFS(Student_Data!D2:D501,9,Student_Data!E2:E501,"A") -> 38

Sheet sumif
A1: 10. Calculate the total marks obtained by students from Delhi.: | B1: =SUMIF(Student_Data!F2:F501,"Delhi",Student_Data!L2:L501) -> 19058
A3: 11. Find total Maths marks for students of Class 8: | B3: =SUMIF(Student_Data!D2:D501,8,Student_Data!G2:G501) -> 6288
A5: 12. Calculate total marks of Female students from Mumbai: | B5: =SUMIFS(Student_Data!L2:L501,Student_Data!C2:C501,"Female",Student_Data!F2:F501,"Mumbai") -> 10649
A7: 13. Find the total attendance of students in Section B: | B7: =SUMIF(Student_Data!E2:E501,"B",Student_Data!N2:N501) -> 13512

Sheet Averageif
A1: 14. Calculate the average percentage of students in Class 10: | B1: =AVERAGEIF(Student_Data!D2:D501,10,Student_Data!M2:M501) -> 69.957009
A3: 15. Find average marks in English for Male students: | B3: =AVERAGEIF(Student_Data!C2:C501,"Male",Student_Data!I2:I501) -> 70.084337
A5: 16. Calculate average percentage of students from Jaipur: | B5: =AVERAGEIF(Student_Data!F2:F501,"Jaipur",Student_Data!M2:M501) -> 71.312121
A7: 17. Find average attendance of students who passed: | B7: =AVERAGEIF(Student_Data!O2:O501,"Pass",Student_Data!N2:N501) -> 80.549098

Sheet Logic_If
A1: Categorize students as “Topper” if percentage is above 85, otherwise “Average”: | B1: 19. Identify students with low attendance (below 70%): | C1: 20. Flag students who failed in any subject (marks below 40 in any subject).
A2: =IF(Student_Data!M2>85,"Topper","Average") -> Average | B2: =IF(Student_Data!N2<70,"Low","OK") -> OK | C2: =IF(OR(Student_Data!G2<40,Student_Data!H2<40,Student_Data!I2<40,Student_Data!J2<40,Student_Data!K2<40),"Fail","Pass") -> Pass
A3: =IF(Student_Data!M3>85,"Topper","Average") -> Topper | B3: =IF(Student_Data!N3<70,"Low","OK") -> OK | C3: =IF(OR(Student_Data!G3<40,Student_Data!H3<40,Student_Data!I3<40,Student_Data!J3<40,Student_Data!K3<40),"Fail","Pass") -> Pass
A4: =IF(Student_Data!M4>85,"Topper","Average") -> Average | B4: =IF(Student_Data!N4<70,"Low","OK") -> OK | C4: =IF(OR(Student_Data!G4<40,Student_Data!H4<40,Student_Data!I4<40,Student_Data!J4<40,Student_Data!K4<40),"Fail","Pass") -> Pass
A5: =IF(Student_Data!M5>85,"Topper","Average") -> Average | B5: =IF(Student_Data!N5<70,"Low","OK") -> OK | C5: =IF(OR(Student_Data!G5<40,Student_Data!H5<40,Student_Data!I5<40,Student_Data!J5<40,Student_Data!K5<40),"Fail","Pass") -> Pass
A6: =IF(Student_Data!M6>85,"Topper","Average") -> Average | B6: =IF(Student_Data!N6<70,"Low","OK") -> OK | C6: =IF(OR(Student_Data!G6<40,Student_Data!H6<40,Student_Data!I6<40,Student_Data!J6<40,Student_Data!K6<40),"Fail","Pass") -> Pass
A7: =IF(Student_Data!M7>85,"Topper","Average") -> Topper | B7: =IF(Student_Data!N7<70,"Low","OK") -> Low | C7: =IF(OR(Student_Data!G7<40,Student_Data!H7<40,Student_Data!I7<40,Student_Data!J7<40,Student_Data!K7<40),"Fail","Pass") -> Pass
A8: =IF(Student_Data!M8>85,"Topper","Average") -> Average | B8: =IF(Student_Data!N8<70,"Low","OK") -> OK | C8: =IF(OR(Student_Data!G8<40,Student_Data!H8<40,Student_Data!I8<40,Student_Data!J8<40,Student_Data!K8<40),"Fail","Pass") -> Pass
A9: =IF(Student_Data!M9>85,"Topper","Average") -> Average | B9: =IF(Student_Data!N9<70,"Low","OK") -> Low | C9: =IF(OR(Student_Data!G9<40,Student_Data!H9<40,Student_Data!I9<40,Student_Data!J9<40,Student_Data!K9<40),"Fail","Pass") -> Pass
A10: =IF(Student_Data!M10>85,"Topper","Average") -> Topper | B10: =IF(Student_Data!N10<70,"Low","OK") -> OK | C10: =IF(OR(Student_Data!G10<40,Student_Data!H10<40,Student_Data!I10<40,Student_Data!J10<40,Student_Data!K10<40),"Fail","Pass") -> Pass
A11: =IF(Student_Data!M11>85,"Topper","Average") -> Average | B11: =IF(Student_Data!N11<70,"Low","OK") -> OK | C11: =IF(OR(Student_Data!G11<40,Student_Data!H11<40,Student_Data!I11<40,Student_Data!J11<40,Student_Data!K11<40),"Fail","Pass") -> Pass
A12: =IF(Student_Data!M12>85,"Topper","Average") -> Average | B12: =IF(Student_Data!N12<70,"Low","OK") -> OK | C12: =IF(OR(Student_Data!G12<40,Student_Data!H12<40,Student_Data!I12<40,Student_Data!J12<40,Student_Data!K12<40),"Fail","Pass") -> Pass
A13: =IF(Student_Data!M13>85,"Topper","Average") -> Average | B13: =IF(Student_Data!N13<70,"Low","OK") -> OK | C13: =IF(OR(Student_Data!G13<40,Student_Data!H13<40,Student_Data!I13<40,Student_Data!J13<40,Student_Data!K13<40),"Fail","Pass") -> Pass
... A501: =IF(Student_Data!M501>85,"Topper","Average") -> Average | B501: =IF(Student_Data!N501<70,"Low","OK") -> OK | C501: =IF(OR(Student_Data!G501<40,Student_Data!H501<40,Student_Data!I501<40,Student_Data!J501<40,Student_Data!K501<40),"Fail","Pass") -> Pass

Sheet XLOOKUP 
A1: 21. Retrieve full details of a student using their Student ID: | B1: {=XLOOKUP("*"&A2,Student_Data!A2:A501,Student_Data!B2:O501,"Not Found",2)} -> Priya Choudhary | C1: Female | D1: 10 | E1: A | F1: Chandigarh | G1: 45 | H1: 97 | I1: 58 | J1: 76 | K1: 71 | L1: 347 | M1: 39.4 | N1: 84 | O1: Pass
A3: 22. Fetch the percentage of a specific student using their ID: | B3: {=XLOOKUP("*"&A2,Student_Data!A2:A501,Student_Data!M2:M501,"Not Found",2)} -> 39.4
A5: 23. Retrieve the city of a student using Student ID: | B5: {=XLOOKUP("*"&A2,Student_Data!A2:A501,Student_Data!F2:F501,"Not Found",2)} -> Chandigarh

Sheet Reports
A1: 24. Display all students whose percentage is greater than 80.: | B1: Student_ID | C1: Full_Name | D1: Gender | E1: Class | F1: Section | G1: Total | H1: Percentage
B2: STD-1001 | C2: Priya Choudhary | D2: Female | E2: 10 | F2: A | G2: 347 | H2: 39.4
B3: STD-1002 | C3: Aarav Verma | D3: Male | E3: 7 | F3: C | G3: 379 | H3: 85.8
B4: STD-1003 | C4: Sai Iyer | D4: Male | E4: 8 | F4: C | G4: 300 | H4: 20
B5: STD-1004 | C5: Ananya Singh | D5: Female | E5: 8 | F5: C | G5: 372 | H5: 74.4
B6: STD-1005 | C6: Shreya Kulkarni | D6: Male | E6: 8 | F6: C | G6: 344 | H6: 68.8
B7: STD-1006 | C7: Aarav Kulkarni | D7: Female | E7: 7 | F7: C | G7: 348 | H7: 89.6
B8: STD-1007 | C8: Meera Gupta | D8: Male | E8: 9 | F8: C | G8: 364 | H8: 82.8
B9: STD-1008 | C9: Kavya Gupta | D9: Male | E9: 7 | F9: C | G9: 316 | H9: 63.2
B10: STD-1009 | C10: Vivaan Verma | D10: Male | E10: 9 | F10: B | G10: 312 | H10: 92.4
B11: STD-1010 | C11: Ananya Banerjee | D11: Female | E11: 10 | F11: A | G11: 353 | H11: 70.6
B12: STD-1011 | C12: Aditya Choudhary | D12: Male | E12: 7 | F12: C | G12: 278 | H12: 25.6
B13: STD-1012 | C13: Priya Patel | D13: Female | E13: 6 | F13: A | G13: 309 | H13: 61.8
B14: STD-1013 | C14: Sai Verma | D14: Female | E14: 8 | F14: B | G14: 297 | H14: 59.4
A15: 25. Show only Female students from Class 9: | B15: STD-1014 | C15: Ananya Yadav | D15: Female | E15: 9 | F15: C | G15: 339 | H15: 97.8
B16: STD-1015 | C16: Pooja Jain | D16: Male | E16: 7 | F16: A | G16: 345 | H16: 69
B17: STD-1016 | C17: Karan Verma | D17: Female | E17: 7 | F17: C | G17: 305 | H17: 61
B18: STD-1017 | C18: Rohan Singh | D18: Male | E18: 6 | F18: C | G18: 365 | H18: 73
B19: STD-1018 | C19: Arjun Reddy | D19: Female | E19: 9 | F19: B | G19: 379 | H19: 75.8
B20: STD-1019 | C20: Karan Iyer | D20: Male | E20: 6 | F20: B | G20: 403 | H20: 80.6
B21: STD-1020 | C21: Arjun Singh | D21: Female | E21: 9 | F21: B | G21: 364 | H21: 72.8
B22: STD-1021 | C22: Ishita Kulkarni | D22: Female | E22: 9 | F22: C | G22: 315 | H22: 63
B23: STD-1022 | C23: Rahul Singh | D23: Male | E23: 10 | F23: A | G23: 338 | H23: 67.6
B24: STD-1023 | C24: Sneha Gupta | D24: Male | E24: 10 | F24: A | G24: 390 | H24: 78
B25: STD-1024 | C25: Shreya Verma | D25: Male | E25: 6 | F25: B | G25: 364 | H25: 72.8
B26: STD-1025 | C26: Ananya Nair | D26: Male | E26: 10 | F26: B | G26: 324 | H26: 64.8
B27: STD-1026 | C27: Neha Kaur | D27: Female | E27: 8 | F27: C | G27: 343 | H27: 68.6
... B501: STD-1500 | C501: Priya Choudhary | D501: Female | E501: 7 | F501: A | G501: 306 | H501: 61.2
A1002: 26. Generate a summary showing average percentage for each Class: | B1002: Class | C1002: AVERAGE of Percentage
C1003: #DIV/0!
B1004: 10 | C1004: 69.957009
B1005: 6 | C1005: 70.677551
B1006: 7 | C1006: 69.588785
B1007: 8 | C1007: 67.459091
B1008: 9 | C1008: 70.596
B1009: Grand Total | C1009: 69.7076
A1011: 27. Generate a report showing total students in each City: | B1011: City | C1011: COUNTA of Student_ID
C1012: 0
B1013: Bhopal | C1013: 64
B1014: Chandigarh | C1014: 69
...
